Workbook

Sheet README
A1: LỘ TRÌNH 180 NGÀY: MẤT GỐC → A0 → A1 → A2 → B1
A3: Sinh từ data/roadmap/*.json + src/content/vocabulary/ · chạy `npm run roadmap` · Ngày bắt đầu: 2026-10-05
A4: Ô nền vàng là ô BẠN GÕ. Ô khác tự tính hoặc do script ghi — gõ vào đó sẽ bị lần chạy sau xoá.
A6: Sheet | B6: Để làm gì | C6: Bạn gõ gì ở đó
A7: TODAY | B7: Hôm nay học gì: ngày thứ mấy, chủ đề, từ mới, từ đến hạn ôn | C7: Không gõ gì
A8: PLAN_180 | B8: 180 dòng lịch học, đã gắn ngày, chủ đề, ngữ pháp, danh sách từ | C8: Không gõ gì
A9: PROGRESS | B9: Sổ theo dõi mỗi ngày | C9: Hoàn thành (Yes/No), 6 điểm kỹ năng, ghi chú
A10: VOCAB | B10: Toàn bộ từ vựng của lộ trình | C10: Không gõ gì
A11: DUE | B11: Sổ ôn lặp lại (1-1-2-4-7-14 ngày) | C11: Mastery 0-5, số lần đúng, ngày vừa ôn
A12: GRAMMAR | B12: Ngữ pháp A0→B1 | C12: Mastery 0-5, ngày học gần nhất
A13: CURRICULUM | B13: 35 chủ đề: mấy ngày trong lịch, đã xong bao nhiêu | C13: Không gõ gì
A14: EXERCISES | B14: Ngân hàng câu hỏi | C14: Không gõ gì
A15: RESOURCES | B15: 5 nguồn học miễn phí | C15: Không gõ gì
A17: Mỗi ngày
A18: 1. Mở TODAY: xem chủ đề, từ mới và số từ ĐẾN HẠN ÔN.
A19: 2. Học theo dòng của PLAN_180: Nghe / Nói / Đọc / Viết, tổng 60 phút.
A20: 3. Tối về: PROGRESS → chọn Yes ở cột Hoàn thành, chấm 6 điểm kỹ năng 0–100.
A21: 4. Ôn: DUE → gõ Mastery 0–5 và ngày vừa ôn; ngày ôn tới tự tính.
A22: 5. Điểm dưới 70%: hôm sau làm lại chủ đề đó trước khi học cái mới.
A24: Số liệu thật của lộ trình này
A25: Ngày 1 = 2026-10-05, ngày 180 = 2027-04-02.
A26: Từ vựng đang có: 248 (A0 167 · A1 29 · A2 26 · B1 26). Cần 1324 từ nữa để phủ kín 180 ngày — bắt đầu hụt từ ngày 24.
A27: Ngữ pháp: 25 điểm · Chủ đề: 35 · Ngày có test: 26 · Test chốt level: A0@tuần 4, A1@tuần 10, A2@tuần 16, B1@tuần 26.
A28: Đổi ngày bắt đầu: sửa data/roadmap/config.json rồi chạy npm run roadmap, cả 180 ngày tính lại.

Sheet TODAY
A1: HÔM NAY HỌC GÌ
A3: Hôm nay là ngày | B3: =TODAY()
A4: Thứ tự trong lộ trình (1→180) | B4: =IFERROR(MATCH(TODAY(),PLAN_180!$B$2:$B$181,0),"—")
A5: Level | B5: =IFERROR(INDEX(PLAN_180!$D$2:$D$181,$B$4),"")
A6: Tuần | B6: =IFERROR(INDEX(PLAN_180!$C$2:$C$181,$B$4),"")
A7: Giai đoạn của tuần | B7: =IFERROR(INDEX(PLAN_180!$E$2:$E$181,$B$4),"")
A8: Dạng bài hôm nay | B8: =IFERROR(INDEX(PLAN_180!$F$2:$F$181,$B$4),"")
A9: Chủ đề | B9: =IFERROR(INDEX(PLAN_180!$H$2:$H$181,$B$4),"")
A10: Ngữ pháp | B10: =IFERROR(INDEX(PLAN_180!$I$2:$I$181,$B$4),"")
A11: Nghe | B11: =IFERROR(INDEX(PLAN_180!$L$2:$L$181,$B$4),"")
A12: Nói | B12: =IFERROR(INDEX(PLAN_180!$M$2:$M$181,$B$4),"")
A13: Đọc | B13: =IFERROR(INDEX(PLAN_180!$N$2:$N$181,$B$4),"")
A14: Viết | B14: =IFERROR(INDEX(PLAN_180!$O$2:$O$181,$B$4),"")
A15: Số phút | B15: =IFERROR(INDEX(PLAN_180!$Q$2:$Q$181,$B$4),"")
A16: Test hôm nay | B16: =IFERROR(INDEX(PLAN_180!$R$2:$R$181,$B$4),"")
A18: # | B18: Từ mới hôm nay | C18: Nghĩa tiếng Việt | D18: Ví dụ | E18: dòng
A19: 1 | B19: =IFERROR(INDEX(VOCAB!$E$2:$E$1500,$E19),"") | C19: =IFERROR(INDEX(VOCAB!$F$2:$F$1500,$E19),"") | D19: =IFERROR(INDEX(VOCAB!$H$2:$H$1500,$E19),"") | E19: =IFERROR(MATCH($A19,VOCAB!$L$2:$L$1500,0),"")
A20: 2 | B20: =IFERROR(INDEX(VOCAB!$E$2:$E$1500,$E20),"") | C20: =IFERROR(INDEX(VOCAB!$F$2:$F$1500,$E20),"") | D20: =IFERROR(INDEX(VOCAB!$H$2:$H$1500,$E20),"") | E20: =IFERROR(MATCH($A20,VOCAB!$L$2:$L$1500,0),"")
A21: 3 | B21: =IFERROR(INDEX(VOCAB!$E$2:$E$1500,$E21),"") | C21: =IFERROR(INDEX(VOCAB!$F$2:$F$1500,$E21),"") | D21: =IFERROR(INDEX(VOCAB!$H$2:$H$1500,$E21),"") | E21: =IFERROR(MATCH($A21,VOCAB!$L$2:$L$1500,0),"")
A22: 4 | B22: =IFERROR(INDEX(VOCAB!$E$2:$E$1500,$E22),"") | C22: =IFERROR(INDEX(VOCAB!$F$2:$F$1500,$E22),"") | D22: =IFERROR(INDEX(VOCAB!$H$2:$H$1500,$E22),"") | E22: =IFERROR(MATCH($A22,VOCAB!$L$2:$L$1500,0),"")
A23: 5 | B23: =IFERROR(INDEX(VOCAB!$E$2:$E$1500,$E23),"") | C23: =IFERROR(INDEX(VOCAB!$F$2:$F$1500,$E23),"") | D23: =IFERROR(INDEX(VOCAB!$H$2:$H$1500,$E23),"") | E23: =IFERROR(MATCH($A23,VOCAB!$L$2:$L$1500,0),"")
A24: 6 | B24: =IFERROR(INDEX(VOCAB!$E$2:$E$1500,$E24),"") | C24: =IFERROR(INDEX(VOCAB!$F$2:$F$1500,$E24),"") | D24: =IFERROR(INDEX(VOCAB!$H$2:$H$1500,$E24),"") | E24: =IFERROR(MATCH($A24,VOCAB!$L$2:$L$1500,0),"")
A25: 7 | B25: =IFERROR(INDEX(VOCAB!$E$2:$E$1500,$E25),"") | C25: =IFERROR(INDEX(VOCAB!$F$2:$F$1500,$E25),"") | D25: =IFERROR(INDEX(VOCAB!$H$2:$H$1500,$E25),"") | E25: =IFERROR(MATCH($A25,VOCAB!$L$2:$L$1500,0),"")
A26: 8 | B26: =IFERROR(INDEX(VOCAB!$E$2:$E$1500,$E26),"") | C26: =IFERROR(INDEX(VOCAB!$F$2:$F$1500,$E26),"") | D26: =IFERROR(INDEX(VOCAB!$H$2:$H$1500,$E26),"") | E26: =IFERROR(MATCH($A26,VOCAB!$L$2:$L$1500,0),"")
A27: 9 | B27: =IFERROR(INDEX(VOCAB!$E$2:$E$1500,$E27),"") | C27: =IFERROR(INDEX(VOCAB!$F$2:$F$1500,$E27),"") | D27: =IFERROR(INDEX(VOCAB!$H$2:$H$1500,$E27),"") | E27: =IFERROR(MATCH($A27,VOCAB!$L$2:$L$1500,0),"")
A28: 10 | B28: =IFERROR(INDEX(VOCAB!$E$2:$E$1500,$E28),"") | C28: =IFERROR(INDEX(VOCAB!$F$2:$F$1500,$E28),"") | D28: =IFERROR(INDEX(VOCAB!$H$2:$H$1500,$E28),"") | E28: =IFERROR(MATCH($A28,VOCAB!$L$2:$L$1500,0),"")
A29: 11 | B29: =IFERROR(INDEX(VOCAB!$E$2:$E$1500,$E29),"") | C29: =IFERROR(INDEX(VOCAB!$F$2:$F$1500,$E29),"") | D29: =IFERROR(INDEX(VOCAB!$H$2:$H$1500,$E29),"") | E29: =IFERROR(MATCH($A29,VOCAB!$L$2:$L$1500,0),"")
A30: 12 | B30: =IFERROR(INDEX(VOCAB!$E$2:$E$1500,$E30),"") | C30: =IFERROR(INDEX(VOCAB!$F$2:$F$1500,$E30),"") | D30: =IFERROR(INDEX(VOCAB!$H$2:$H$1500,$E30),"") | E30: =IFERROR(MATCH($A30,VOCAB!$L$2:$L$1500,0),"")
... A32: 14 | B32: =IFERROR(INDEX(VOCAB!$E$2:$E$1500,$E32),"") | C32: =IFERROR(INDEX(VOCAB!$F$2:$F$1500,$E32),"") | D32: =IFERROR(INDEX(VOCAB!$H$2:$H$1500,$E32),"") | E32: =IFERROR(MATCH($A32,VOCAB!$L$2:$L$1500,0),"")
A34: # | B34: Từ đến hạn ôn | C34: Nghĩa tiếng Việt | D34: Ví dụ | E34: dòng
A35: 1 | B35: =IFERROR(INDEX(DUE!$B$2:$B$1500,$E35),"") | C35: =IFERROR(INDEX(DUE!$C$2:$C$1500,$E35),"") | D35: =IFERROR(INDEX(DUE!$D$2:$D$1500,$E35),"") | E35: =IFERROR(MATCH($A35,DUE!$J$2:$J$1500,0),"")
A36: 2 | B36: =IFERROR(INDEX(DUE!$B$2:$B$1500,$E36),"") | C36: =IFERROR(INDEX(DUE!$C$2:$C$1500,$E36),"") | D36: =IFERROR(INDEX(DUE!$D$2:$D$1500,$E36),"") | E36: =IFERROR(MATCH($A36,DUE!$J$2:$J$1500,0),"")
A37: 3 | B37: =IFERROR(INDEX(DUE!$B$2:$B$1500,$E37),"") | C37: =IFERROR(INDEX(DUE!$C$2:$C$1500,$E37),"") | D37: =IFERROR(INDEX(DUE!$D$2:$D$1500,$E37),"") | E37: =IFERROR(MATCH($A37,DUE!$J$2:$J$1500,0),"")
A38: 4 | B38: =IFERROR(INDEX(DUE!$B$2:$B$1500,$E38),"") | C38: =IFERROR(INDEX(DUE!$C$2:$C$1500,$E38),"") | D38: =IFERROR(INDEX(DUE!$D$2:$D$1500,$E38),"") | E38: =IFERROR(MATCH($A38,DUE!$J$2:$J$1500,0),"")
A39: 5 | B39: =IFERROR(INDEX(DUE!$B$2:$B$1500,$E39),"") | C39: =IFERROR(INDEX(DUE!$C$2:$C$1500,$E39),"") | D39: =IFERROR(INDEX(DUE!$D$2:$D$1500,$E39),"") | E39: =IFERROR(MATCH($A39,DUE!$J$2:$J$1500,0),"")
A40: 6 | B40: =IFERROR(INDEX(DUE!$B$2:$B$1500,$E40),"") | C40: =IFERROR(INDEX(DUE!$C$2:$C$1500,$E40),"") | D40: =IFERROR(INDEX(DUE!$D$2:$D$1500,$E40),"") | E40: =IFERROR(MATCH($A40,DUE!$J$2:$J$1500,0),"")
A41: 7 | B41: =IFERROR(INDEX(DUE!$B$2:$B$1500,$E41),"") | C41: =IFERROR(INDEX(DUE!$C$2:$C$1500,$E41),"") | D41: =IFERROR(INDEX(DUE!$D$2:$D$1500,$E41),"") | E41: =IFERROR(MATCH($A41,DUE!$J$2:$J$1500,0),"")
A42: 8 | B42: =IFERROR(INDEX(DUE!$B$2:$B$1500,$E42),"") | C42: =IFERROR(INDEX(DUE!$C$2:$C$1500,$E42),"") | D42: =IFERROR(INDEX(DUE!$D$2:$D$1500,$E42),"") | E42: =IFERROR(MATCH($A42,DUE!$J$2:$J$1500,0),"")
A43: 9 | B43: =IFERROR(INDEX(DUE!$B$2:$B$1500,$E43),"") | C43: =IFERROR(INDEX(DUE!$C$2:$C$1500,$E43),"") | D43: =IFERROR(INDEX(DUE!$D$2:$D$1500,$E43),"") | E43: =IFERROR(MATCH($A43,DUE!$J$2:$J$1500,0),"")
A44: 10 | B44: =IFERROR(INDEX(DUE!$B$2:$B$1500,$E44),"") | C44: =IFERROR(INDEX(DUE!$C$2:$C$1500,$E44),"") | D44: =IFERROR(INDEX(DUE!$D$2:$D$1500,$E44),"") | E44: =IFERROR(MATCH($A44,DUE!$J$2:$J$1500,0),"")
...

Sheet PLAN_180
A1: Ngày | B1: Ngày lịch | C1: Tuần | D1: Level | E1: Giai đoạn tuần | F1: Dạng bài | G1: CurriculumID | H1: Chủ đề | I1: Ngữ pháp | J1: Từ hôm nay (ID) | K1: Số từ | L1: Nghe | M1: Nói | N1: Đọc | O1: Viết | P1: Bài tập | Q1: Phút | R1: Test | S1: Trạng thái | T1: Nguồn từ
A2: 1 | B2: 46300 | C2: 1 | D2: A0 | E2: Foundation & survival English | F2: New concept | G2: A0-001 | H2: Alphabet & spelling | I2: — | J2: a0_alpha_001 · a0_alpha_002 · a0_alpha_003 · a0_alpha_004 · a0_alpha_005 · a0_alpha_006 · a0_alpha_007 · a0_alpha_008 | K2: 8 | L2: letter sounds | M2: spell your name | N2: read letters | O2: write the alphabet | P2: — | Q2: 60 | R2: — | S2: =IF(PROGRESS!$E2="Yes","Xong","Chưa làm") | T2: đủ từ
A3: 2 | B3: 46301 | C3: 1 | D3: A0 | E3: Foundation & survival English | F3: Guided practice | G3: A0-001 | H3: Alphabet & spelling | I3: — | J3: a0_alpha_009 · a0_alpha_010 · a0_sound_011 · a0_sound_012 · a0_sound_013 · a0_sound_014 · a0_sound_015 · a0_sound_016 | K3: 8 | L3: letter sounds | M3: spell your name | N3: read letters | O3: write the alphabet | P3: — | Q3: 60 | R3: — | S3: =IF(PROGRESS!$E3="Yes","Xong","Chưa làm") | T3: đủ từ
A4: 3 | B4: 46302 | C4: 1 | D4: A0 | E4: Foundation & survival English | F4: Listening + shadowing | G4: A0-002 | H4: Vowels & consonants | I4: — | J4: a0_sound_017 · a0_sound_018 · a0_num_019 · a0_num_020 · a0_num_021 · a0_num_022 · a0_num_023 · a0_num_024 | K4: 8 | L4: identify sounds | M4: repeat sounds | N4: sound recognition | O4: — | P4: — | Q4: 60 | R4: — | S4: =IF(PROGRESS!$E4="Yes","Xong","Chưa làm") | T4: đủ từ
A5: 4 | B5: 46303 | C5: 1 | D5: A0 | E5: Foundation & survival English | F5: Speaking drill | G5: A0-002 | H5: Vowels & consonants | I5: — | J5: a0_num_025 · a0_num_026 · a0_num_027 · a0_num_028 · a0_num_029 · a0_num_030 · a0_num_031 · a0_num_032 | K5: 8 | L5: identify sounds | M5: repeat sounds | N5: sound recognition | O5: — | P5: — | Q5: 60 | R5: — | S5: =IF(PROGRESS!$E5="Yes","Xong","Chưa làm") | T5: đủ từ
A6: 5 | B6: 46304 | C6: 1 | D6: A0 | E6: Foundation & survival English | F6: Reading + vocabulary | G6: A0-004 | H6: Greetings & introductions | I6: GA01 Verb BE | J6: a0_num_033 · a0_num_034 · a0_num_035 · a0_num_036 · a0_num_037 · a0_num_038 · a0_num_039 · a0_num_040 | K6: 8 | L6: intro dialogue | M6: introduce yourself | N6: read a mini dialogue | O6: write an introduction | P6: E002, E003 | Q6: 60 | R6: — | S6: =IF(PROGRESS!$E6="Yes","Xong","Chưa làm") | T6: đủ từ
A7: 6 | B7: 46305 | C7: 1 | D7: A0 | E7: Foundation & survival English | F7: Writing + correction | G7: A0-004 | H7: Greetings & introductions | I7: GA01 Verb BE | J7: a0_num_041 · a0_num_042 · a0_num_043 · a0_num_044 · a0_num_045 · a0_num_046 · a0_num_047 · a0_greet_048 | K7: 8 | L7: intro dialogue | M7: introduce yourself | N7: read a mini dialogue | O7: write an introduction | P7: E002, E003 | Q7: 60 | R7: — | S7: =IF(PROGRESS!$E7="Yes","Xong","Chưa làm") | T7: đủ từ
A8: 7 | B8: 46306 | C8: 1 | D8: A0 | E8: Foundation & survival English | F8: Weekly review | G8: — | H8: Ôn tổng hợp tuần 1 | I8: — | J8: — | K8: 0 | L8: Ôn theo sheet DUE | M8: Nói lại 5 câu của tuần | N8: Đọc lại văn bản tuần | O8: Viết lại đoạn đã sửa | P8: E002, E003 | Q8: 60 | R8: Test tuần 1 | S8: =IF(PROGRESS!$E8="Yes","Xong","Chưa làm") | T8: ngày ôn, không thêm từ
A9: 8 | B9: 46307 | C9: 2 | D9: A0 | E9: Pronunciation & basic vocabulary | F9: New concept | G9: A0-003 | H9: Numbers & time | I9: — | J9: a0_greet_049 · a0_greet_050 · a0_greet_051 · a0_greet_052 · a0_greet_053 · a0_greet_054 · a0_greet_055 · a0_greet_056 | K9: 8 | L9: short number audio | M9: say the time | N9: read numbers | O9: write numbers | P9: — | Q9: 60 | R9: — | S9: =IF(PROGRESS!$E9="Yes","Xong","Chưa làm") | T9: đủ từ
A10: 9 | B10: 46308 | C10: 2 | D10: A0 | E10: Pronunciation & basic vocabulary | F10: Guided practice | G10: A0-003 | H10: Numbers & time | I10: — | J10: a0_greet_057 · a0_greet_058 · a0_greet_059 · a0_greet_060 · a0_greet_061 · cur_v001 · cur_v002 · cur_v005 | K10: 8 | L10: short number audio | M10: say the time | N10: read numbers | O10: write numbers | P10: — | Q10: 60 | R10: — | S10: =IF(PROGRESS!$E10="Yes","Xong","Chưa làm") | T10: đủ từ
A11: 10 | B11: 46309 | C11: 2 | D11: A0 | E11: Pronunciation & basic vocabulary | F11: Listening + shadowing | G11: A0-003 | H11: Numbers & time | I11: — | J11: a0_pron_062 · a0_pron_063 · a0_pron_064 · a0_pron_065 · a0_pron_066 · a0_pron_067 · a0_pron_068 · a0_pron_069 | K11: 8 | L11: short number audio | M11: say the time | N11: read numbers | O11: write numbers | P11: — | Q11: 60 | R11: — | S11: =IF(PROGRESS!$E11="Yes","Xong","Chưa làm") | T11: đủ từ
A12: 11 | B12: 46310 | C12: 2 | D12: A0 | E12: Pronunciation & basic vocabulary | F12: Speaking drill | G12: A0-005 | H12: Pronouns & BE | I12: GA01 Verb BE; GA02 Subject pronouns | J12: a0_pron_070 · a0_pron_071 · a0_pron_072 · a0_pron_073 · a0_pron_074 · a0_pron_075 · a0_pron_076 · a0_pron_077 | K12: 8 | L12: BE sentences | M12: make 10 sentences | N12: read sentences | O12: write 10 sentences | P12: E001 | Q12: 60 | R12: — | S12: =IF(PROGRESS!$E12="Yes","Xong","Chưa làm") | T12: đủ từ
A13: 12 | B13: 46311 | C13: 2 | D13: A0 | E13: Pronunciation & basic vocabulary | F13: Reading + vocabulary | G13: A0-005 | H13: Pronouns & BE | I13: GA01 Verb BE; GA02 Subject pronouns | J13: a0_pron_078 · a0_pron_079 · a0_pron_080 · a0_obj_081 · a0_obj_082 · a0_obj_083 · a0_obj_084 · a0_obj_085 | K13: 8 | L13: BE sentences | M13: make 10 sentences | N13: read sentences | O13: write 10 sentences | P13: E001 | Q13: 60 | R13: — | S13: =IF(PROGRESS!$E13="Yes","Xong","Chưa làm") | T13: đủ từ
... A181: 180 | B181: 46479 | C181: 26 | D181: B1 | E181: Final assessment & consolidation | F181: Weekly review | G181: — | H181: Ôn tổng hợp tuần 26 | I181: — | J181: — | K181: 0 | L181: Ôn theo sheet DUE | M181: Nói lại 5 câu của tuần | N181: Đọc lại văn bản tuần | O181: Viết lại đoạn đã sửa | P181: — | Q181: 60 | R181: Test chốt B1 (mục tiêu 80% + mock test đạt mục tiêu) | S181: =IF(PROGRESS!$E181="Yes","Xong","Chưa làm") | T181: ngày ôn, không thêm từ

Sheet VOCAB
A1: ID | B1: Level | C1: Nhóm | D1: Chủ đề | E1: Từ | F1: Nghĩa VI | G1: IPA | H1: Ví dụ | I1: Collocation | J1: Nguồn dữ liệu | K1: Ngày học | L1: Thứ tự hôm nay
A2: a0_alpha_001 | B2: A0 | C2: alphabet | D2: A0-001 | E2: letter | F2: chữ cái | G2: /ˈlet̬ɚ/ | H2: The English alphabet has 26 letters. | I2: a capital letter, letter name | J2: data/roadmap | K2: 46300 | L2: =IF($K2="","",IF($K2=TODAY(),COUNTIF($K$2:$K2,TODAY()),""))
A3: a0_alpha_002 | B3: A0 | C3: alphabet | D3: A0-001 | E3: alphabet | F3: bảng chữ cái | G3: /ˈælfəbet/ | H3: I recite the alphabet from A to Z. | I3: the English alphabet | J3: data/roadmap | K3: 46300 | L3: =IF($K3="","",IF($K3=TODAY(),COUNTIF($K$2:$K3,TODAY()),""))
A4: a0_alpha_003 | B4: A0 | C4: alphabet | D4: A0-001 | E4: spell | F4: đánh vần | G4: /spɛl/ | H4: Can you spell your city? | I4: spell it slowly | J4: data/roadmap | K4: 46300 | L4: =IF($K4="","",IF($K4=TODAY(),COUNTIF($K$2:$K4,TODAY()),""))
A5: a0_alpha_004 | B5: A0 | C5: sound | D5: A0-001 | E5: vowel | F5: nguyên âm | G5: /ˈvaʊəl/ | H5: A, E, I, O, U are vowels. | I5: a short vowel | J5: data/roadmap | K5: 46300 | L5: =IF($K5="","",IF($K5=TODAY(),COUNTIF($K$2:$K5,TODAY()),""))
A6: a0_alpha_005 | B6: A0 | C6: sound | D6: A0-001 | E6: consonant | F6: phụ âm | G6: /ˈkɑnsənənt/ | H6: The letter T is a consonant. | I6: a final consonant | J6: data/roadmap | K6: 46300 | L6: =IF($K6="","",IF($K6=TODAY(),COUNTIF($K$2:$K6,TODAY()),""))
A7: a0_alpha_006 | B7: A0 | C7: alphabet | D7: A0-001 | E7: capital | F7: viết hoa | G7: /ˈkæpət̬əl/ | H7: Write your name with a capital letter. | I7: a capital letter | J7: data/roadmap | K7: 46300 | L7: =IF($K7="","",IF($K7=TODAY(),COUNTIF($K$2:$K7,TODAY()),""))
A8: a0_alpha_007 | B8: A0 | C8: sound | D8: A0-001 | E8: sound | F8: âm | G8: /saʊnd/ | H8: The sound of TH is new for me. | I8: a short sound, sound like | J8: data/roadmap | K8: 46300 | L8: =IF($K8="","",IF($K8=TODAY(),COUNTIF($K$2:$K8,TODAY()),""))
A9: a0_alpha_008 | B9: A0 | C9: verb | D9: A0-001 | E9: write | F9: viết | G9: /raɪt/ | H9: I write my name on the paper. | I9: write a letter, write down | J9: data/roadmap | K9: 46300 | L9: =IF($K9="","",IF($K9=TODAY(),COUNTIF($K$2:$K9,TODAY()),""))
A10: a0_alpha_009 | B10: A0 | C10: verb | D10: A0-001 | E10: say | F10: nói | G10: /seɪ/ | H10: Say the word after me. | I10: say it again | J10: data/roadmap | K10: 46301 | L10: =IF($K10="","",IF($K10=TODAY(),COUNTIF($K$2:$K10,TODAY()),""))
A11: a0_alpha_010 | B11: A0 | C11: alphabet | D11: A0-001 | E11: English | F11: tiếng Anh | G11: /ˈɪŋɡlɪʃ/ | H11: I study English every morning. | I11: speak English, an English teacher | J11: data/roadmap | K11: 46301 | L11: =IF($K11="","",IF($K11=TODAY(),COUNTIF($K$2:$K11,TODAY()),""))
A12: a0_sound_011 | B12: A0 | C12: sound | D12: A0-002 | E12: ship | F12: con tàu | G12: /ʃɪp/ | H12: The ship is very big. | I12: a big ship | J12: data/roadmap | K12: 46301 | L12: =IF($K12="","",IF($K12=TODAY(),COUNTIF($K$2:$K12,TODAY()),""))
A13: a0_sound_012 | B13: A0 | C13: sound | D13: A0-002 | E13: sheep | F13: con cừu | G13: /ʃip/ | H13: The sheep eats grass near the road. | I13: a white sheep | J13: data/roadmap | K13: 46301 | L13: =IF($K13="","",IF($K13=TODAY(),COUNTIF($K$2:$K13,TODAY()),""))
... A171: cur_v009 | B171: A1 | C171: health | D171: A1-019 | E171: healthy | F171: khỏe mạnh | G171: /ˈhelθi/ | H171: Walking is a healthy habit. | I171: healthy food, healthy lifestyle | J171: data/roadmap | K171: 46328 | L171: =IF($K171="","",IF($K171=TODAY(),COUNTIF($K$2:$K171,TODAY()),""))
A172: a1_daily_001 | B172: A1 | C172: daily-life | D172: — | E172: breakfast | F172: bữa sáng | H172: I have breakfast at seven o'clock. | I172: have breakfast, breakfast time | J172: src/content/vocabulary/a1/daily-life.json | K172: 46328 | L172: =IF($K172="","",IF($K172=TODAY(),COUNTIF($K$2:$K172,TODAY()),""))
A173: a1_daily_002 | B173: A1 | C173: daily-life | D173: — | E173: window | F173: cửa sổ | H173: She opened the window to let in some air. | I173: open the window, by the window | J173: src/content/vocabulary/a1/daily-life.json | K173: 46328 | L173: =IF($K173="","",IF($K173=TODAY(),COUNTIF($K$2:$K173,TODAY()),""))
A174: a1_daily_003 | B174: A1 | C174: daily-life | D174: — | E174: mirror | F174: cái gương | H174: He looked at himself in the mirror. | I174: in the mirror, a full-length mirror | J174: src/content/vocabulary/a1/daily-life.json | K174: 46328 | L174: =IF($K174="","",IF($K174=TODAY(),COUNTIF($K$2:$K174,TODAY()),""))
A175: a1_daily_004 | B175: A1 | C175: daily-life | D175: — | E175: umbrella | F175: cái ô | H175: Take an umbrella — it might rain. | I175: open an umbrella, bring an umbrella | J175: src/content/vocabulary/a1/daily-life.json | K175: 46328 | L175: =IF($K175="","",IF($K175=TODAY(),COUNTIF($K$2:$K175,TODAY()),""))
A176: a1_daily_005 | B176: A1 | C176: daily-life | D176: — | E176: kitchen | F176: nhà bếp | H176: The keys are on the kitchen table. | I176: kitchen table, in the kitchen | J176: src/content/vocabulary/a1/daily-life.json | K176: 46328 | L176: =IF($K176="","",IF($K176=TODAY(),COUNTIF($K$2:$K176,TODAY()),""))
A177: a1_daily_006 | B177: A1 | C177: daily-life | D177: — | E177: bedroom | F177: phòng ngủ | H177: My bedroom is small but bright. | I177: master bedroom, go to the bedroom | J177: src/content/vocabulary/a1/daily-life.json | K177: 46328 | L177: =IF($K177="","",IF($K177=TODAY(),COUNTIF($K$2:$K177,TODAY()),""))
A178: a1_daily_007 | B178: A1 | C178: daily-life | D178: — | E178: wallet | F178: cái ví | H178: I left my wallet at home. | I178: lose your wallet, leather wallet | J178: src/content/vocabulary/a1/daily-life.json | K178: 46328 | L178: =IF($K178="","",IF($K178=TODAY(),COUNTIF($K$2:$K178,TODAY()),""))
A179: a1_daily_008 | B179: A1 | C179: daily-life | D179: — | E179: key | F179: chìa khoá | H179: Do you have a key for this door? | I179: car key, lose the key | J179: src/content/vocabulary/a1/daily-life.json | K179: 46329 | L179: =IF($K179="","",IF($K179=TODAY(),COUNTIF($K$2:$K179,TODAY()),""))
A180: a1_daily_009 | B180: A1 | C180: daily-life | D180: — | E180: bottle | F180: cái chai | H180: Drink a bottle of water every day. | I180: a bottle of water, glass bottle | J180: src/content/vocabulary/a1/daily-life.json | K180: 46329 | L180: =IF($K180="","",IF($K180=TODAY(),COUNTIF($K$2:$K180,TODAY()),""))
A181: a1_daily_010 | B181: A1 | C181: daily-life | D181: — | E181: routine | F181: thói quen hằng ngày | H181: Running is part of my morning routine. | I181: daily routine, morning routine | J181: src/content/vocabulary/a1/daily-life.json | K181: 46329 | L181: =IF($K181="","",IF($K181=TODAY(),COUNTIF($K$2:$K181,TODAY()),""))
A182: a1_daily_011 | B182: A1 | C182: daily-life | D182: — | E182: neighbour | F182: hàng xóm | H182: Our neighbour has a big brown dog. | I182: next-door neighbour, a friendly neighbour | J182: src/content/vocabulary/a1/daily-life.json | K182: 46329 | L182: =IF($K182="","",IF($K182=TODAY(),COUNTIF($K$2:$K182,TODAY()),""))
A183: a1_daily_012 | B183: A1 | C183: daily-life | D183: — | E183: laundry | F183: quần áo cần giặt | H183: I do the laundry every Sunday. | I183: do the laundry, a pile of laundry | J183: src/content/vocabulary/a1/daily-life.json | K183: 46329 | L183: =IF($K183="","",IF($K183=TODAY(),COUNTIF($K$2:$K183,TODAY()),""))
... A197: a1_travel_012 | B197: A1 | C197: travel | D197: — | E197: reservation | F197: sự đặt chỗ trước | H197: I have a reservation for two people. | I197: make a reservation, cancel a reservation | J197: src/content/vocabulary/a1/travel.json | K197: 46330 | L197: =IF($K197="","",IF($K197=TODAY(),COUNTIF($K$2:$K197,TODAY()),""))
A198: cur_v011 | B198: A2 | C198: work-study | D198: A2-027 | E198: improve | F198: cải thiện | G198: /ɪmˈpruːv/ | H198: I want to improve my English. | I198: improve skills | J198: data/roadmap | K198: 46370 | L198: =IF($K198="","",IF($K198=TODAY(),COUNTIF($K$2:$K198,TODAY()),""))
A199: cur_v012 | B199: A2 | C199: technology | D199: A2-028 | E199: device | F199: thiết bị | G199: /dɪˈvaɪs/ | H199: This device is easy to use. | I199: mobile device | J199: data/roadmap | K199: 46370 | L199: =IF($K199="","",IF($K199=TODAY(),COUNTIF($K$2:$K199,TODAY()),""))
A200: a2_act_001 | B200: A2 | C200: daily-activities | D200: — | E200: exercise | F200: tập thể dục | H200: I do exercise three times a week. | I200: get exercise, do exercise | J200: src/content/vocabulary/a2/daily-activities.json | K200: 46370 | L200: =IF($K200="","",IF($K200=TODAY(),COUNTIF($K$2:$K200,TODAY()),""))
A201: a2_act_002 | B201: A2 | C201: daily-activities | D201: — | E201: housework | F201: việc nhà | H201: We share the housework every evening. | I201: do housework, a day of housework | J201: src/content/vocabulary/a2/daily-activities.json | K201: 46370 | L201: =IF($K201="","",IF($K201=TODAY(),COUNTIF($K$2:$K201,TODAY()),""))
A202: a2_act_003 | B202: A2 | C202: daily-activities | D202: — | E202: homework | F202: bài tập về nhà | H202: She finished her homework before dinner. | I202: do homework, a lot of homework | J202: src/content/vocabulary/a2/daily-activities.json | K202: 46370 | L202: =IF($K202="","",IF($K202=TODAY(),COUNTIF($K$2:$K202,TODAY()),""))
A203: a2_act_004 | B203: A2 | C203: daily-activities | D203: — | E203: weekend | F203: cuối tuần | H203: What are you doing this weekend? | I203: at the weekend, long weekend | J203: src/content/vocabulary/a2/daily-activities.json | K203: 46370 | L203: =IF($K203="","",IF($K203=TODAY(),COUNTIF($K$2:$K203,TODAY()),""))
A204: a2_act_005 | B204: A2 | C204: daily-activities | D204: — | E204: holiday | F204: kỳ nghỉ | H204: They are on holiday in Nha Trang. | I204: go on holiday, summer holiday | J204: src/content/vocabulary/a2/daily-activities.json | K204: 46370 | L204: =IF($K204="","",IF($K204=TODAY(),COUNTIF($K$2:$K204,TODAY()),""))
A205: a2_act_006 | B205: A2 | C205: daily-activities | D205: — | E205: birthday | F205: sinh nhật | H205: His birthday is next Monday. | I205: birthday party, happy birthday | J205: src/content/vocabulary/a2/daily-activities.json | K205: 46370 | L205: =IF($K205="","",IF($K205=TODAY(),COUNTIF($K$2:$K205,TODAY()),""))
A206: a2_act_007 | B206: A2 | C206: daily-activities | D206: — | E206: concert | F206: buổi hòa nhạc | H206: We bought tickets for the concert. | I206: give a concert, a rock concert | J206: src/content/vocabulary/a2/daily-activities.json | K206: 46370 | L206: =IF($K206="","",IF($K206=TODAY(),COUNTIF($K$2:$K206,TODAY()),""))
A207: a2_act_008 | B207: A2 | C207: daily-activities | D207: — | E207: cinema | F207: rạp phim | H207: The cinema is next to the bookshop. | I207: go to the cinema, an old cinema | J207: src/content/vocabulary/a2/daily-activities.json | K207: 46370 | L207: =IF($K207="","",IF($K207=TODAY(),COUNTIF($K$2:$K207,TODAY()),""))
A208: a2_act_009 | B208: A2 | C208: daily-activities | D208: — | E208: restaurant | F208: nhà hàng | H208: We had lunch at a small restaurant. | I208: a cheap restaurant, run a restaurant | J208: src/content/vocabulary/a2/daily-activities.json | K208: 46370 | L208: =IF($K208="","",IF($K208=TODAY(),COUNTIF($K$2:$K208,TODAY()),""))
A209: a2_act_010 | B209: A2 | C209: daily-activities | D209: — | E209: photograph | F209: bức ảnh | H209: She took a photograph of the bay. | I209: take a photograph, an old photograph | J209: src/content/vocabulary/a2/daily-activities.json | K209: 46370 | L209: =IF($K209="","",IF($K209=TODAY(),COUNTIF($K$2:$K209,TODAY()),""))
A210: a2_act_011 | B210: A2 | C210: daily-activities | D210: — | E210: message | F210: tin nhắn | H210: Leave me a message if I am out. | I210: send a message, leave a message | J210: src/content/vocabulary/a2/daily-activities.json | K210: 46371 | L210: =IF($K210="","",IF($K210=TODAY(),COUNTIF($K$2:$K210,TODAY()),""))
...

Sheet DUE
A1: ID | B1: Từ | C1: Nghĩa VI | D1: Ví dụ | E1: Mastery 0-5 | F1: Số lần đúng | G1: Ngày ôn gần nhất | H1: Ngày ôn tới | I1: Trạng thái | J1: Thứ tự đến hạn | K1: Ghi chú
A2: a0_alpha_001 | B2: =IFERROR(VLOOKUP($A2,VOCAB!$A$2:$L$1500,5,FALSE),"") | C2: =IFERROR(VLOOKUP($A2,VOCAB!$A$2:$L$1500,6,FALSE),"") | D2: =IFERROR(VLOOKUP($A2,VOCAB!$A$2:$L$1500,8,FALSE),"") | H2: =IF($G2="","",$G2+IF($E2=0,1,IF($E2=1,1,IF($E2=2,2,IF($E2=3,4,IF($E2=4,7,14)))))) | I2: =IF($G2="","Mới",IF($H2<=TODAY(),"ĐẾN HẠN","Lịch")) | J2: =IF($I2="ĐẾN HẠN",COUNTIF($I$2:$I2,"ĐẾN HẠN"),"")
A3: a0_alpha_002 | B3: =IFERROR(VLOOKUP($A3,VOCAB!$A$2:$L$1500,5,FALSE),"") | C3: =IFERROR(VLOOKUP($A3,VOCAB!$A$2:$L$1500,6,FALSE),"") | D3: =IFERROR(VLOOKUP($A3,VOCAB!$A$2:$L$1500,8,FALSE),"") | H3: =IF($G3="","",$G3+IF($E3=0,1,IF($E3=1,1,IF($E3=2,2,IF($E3=3,4,IF($E3=4,7,14)))))) | I3: =IF($G3="","Mới",IF($H3<=TODAY(),"ĐẾN HẠN","Lịch")) | J3: =IF($I3="ĐẾN HẠN",COUNTIF($I$2:$I3,"ĐẾN HẠN"),"")
A4: a0_alpha_003 | B4: =IFERROR(VLOOKUP($A4,VOCAB!$A$2:$L$1500,5,FALSE),"") | C4: =IFERROR(VLOOKUP($A4,VOCAB!$A$2:$L$1500,6,FALSE),"") | D4: =IFERROR(VLOOKUP($A4,VOCAB!$A$2:$L$1500,8,FALSE),"") | H4: =IF($G4="","",$G4+IF($E4=0,1,IF($E4=1,1,IF($E4=2,2,IF($E4=3,4,IF($E4=4,7,14)))))) | I4: =IF($G4="","Mới",IF($H4<=TODAY(),"ĐẾN HẠN","Lịch")) | J4: =IF($I4="ĐẾN HẠN",COUNTIF($I$2:$I4,"ĐẾN HẠN"),"")
A5: a0_alpha_004 | B5: =IFERROR(VLOOKUP($A5,VOCAB!$A$2:$L$1500,5,FALSE),"") | C5: =IFERROR(VLOOKUP($A5,VOCAB!$A$2:$L$1500,6,FALSE),"") | D5: =IFERROR(VLOOKUP($A5,VOCAB!$A$2:$L$1500,8,FALSE),"") | H5: =IF($G5="","",$G5+IF($E5=0,1,IF($E5=1,1,IF($E5=2,2,IF($E5=3,4,IF($E5=4,7,14)))))) | I5: =IF($G5="","Mới",IF($H5<=TODAY(),"ĐẾN HẠN","Lịch")) | J5: =IF($I5="ĐẾN HẠN",COUNTIF($I$2:$I5,"ĐẾN HẠN"),"")
A6: a0_alpha_005 | B6: =IFERROR(VLOOKUP($A6,VOCAB!$A$2:$L$1500,5,FALSE),"") | C6: =IFERROR(VLOOKUP($A6,VOCAB!$A$2:$L$1500,6,FALSE),"") | D6: =IFERROR(VLOOKUP($A6,VOCAB!$A$2:$L$1500,8,FALSE),"") | H6: =IF($G6="","",$G6+IF($E6=0,1,IF($E6=1,1,IF($E6=2,2,IF($E6=3,4,IF($E6=4,7,14)))))) | I6: =IF($G6="","Mới",IF($H6<=TODAY(),"ĐẾN HẠN","Lịch")) | J6: =IF($I6="ĐẾN HẠN",COUNTIF($I$2:$I6,"ĐẾN HẠN"),"")
A7: a0_alpha_006 | B7: =IFERROR(VLOOKUP($A7,VOCAB!$A$2:$L$1500,5,FALSE),"") | C7: =IFERROR(VLOOKUP($A7,VOCAB!$A$2:$L$1500,6,FALSE),"") | D7: =IFERROR(VLOOKUP($A7,VOCAB!$A$2:$L$1500,8,FALSE),"") | H7: =IF($G7="","",$G7+IF($E7=0,1,IF($E7=1,1,IF($E7=2,2,IF($E7=3,4,IF($E7=4,7,14)))))) | I7: =IF($G7="","Mới",IF($H7<=TODAY(),"ĐẾN HẠN","Lịch")) | J7: =IF($I7="ĐẾN HẠN",COUNTIF($I$2:$I7,"ĐẾN HẠN"),"")
A8: a0_alpha_007 | B8: =IFERROR(VLOOKUP($A8,VOCAB!$A$2:$L$1500,5,FALSE),"") | C8: =IFERROR(VLOOKUP($A8,VOCAB!$A$2:$L$1500,6,FALSE),"") | D8: =IFERROR(VLOOKUP($A8,VOCAB!$A$2:$L$1500,8,FALSE),"") | H8: =IF($G8="","",$G8+IF($E8=0,1,IF($E8=1,1,IF($E8=2,2,IF($E8=3,4,IF($E8=4,7,14)))))) | I8: =IF($G8="","Mới",IF($H8<=TODAY(),"ĐẾN HẠN","Lịch")) | J8: =IF($I8="ĐẾN HẠN",COUNTIF($I$2:$I8,"ĐẾN HẠN"),"")
A9: a0_alpha_008 | B9: =IFERROR(VLOOKUP($A9,VOCAB!$A$2:$L$1500,5,FALSE),"") | C9: =IFERROR(VLOOKUP($A9,VOCAB!$A$2:$L$1500,6,FALSE),"") | D9: =IFERROR(VLOOKUP($A9,VOCAB!$A$2:$L$1500,8,FALSE),"") | H9: =IF($G9="","",$G9+IF($E9=0,1,IF($E9=1,1,IF($E9=2,2,IF($E9=3,4,IF($E9=4,7,14)))))) | I9: =IF($G9="","Mới",IF($H9<=TODAY(),"ĐẾN HẠN","Lịch")) | J9: =IF($I9="ĐẾN HẠN",COUNTIF($I$2:$I9,"ĐẾN HẠN"),"")
A10: a0_alpha_009 | B10: =IFERROR(VLOOKUP($A10,VOCAB!$A$2:$L$1500,5,FALSE),"") | C10: =IFERROR(VLOOKUP($A10,VOCAB!$A$2:$L$1500,6,FALSE),"") | D10: =IFERROR(VLOOKUP($A10,VOCAB!$A$2:$L$1500,8,FALSE),"") | H10: =IF($G10="","",$G10+IF($E10=0,1,IF($E10=1,1,IF($E10=2,2,IF($E10=3,4,IF($E10=4,7,14)))))) | I10: =IF($G10="","Mới",IF($H10<=TODAY(),"ĐẾN HẠN","Lịch")) | J10: =IF($I10="ĐẾN HẠN",COUNTIF($I$2:$I10,"ĐẾN HẠN"),"")
A11: a0_alpha_010 | B11: =IFERROR(VLOOKUP($A11,VOCAB!$A$2:$L$1500,5,FALSE),"") | C11: =IFERROR(VLOOKUP($A11,VOCAB!$A$2:$L$1500,6,FALSE),"") | D11: =IFERROR(VLOOKUP($A11,VOCAB!$A$2:$L$1500,8,FALSE),"") | H11: =IF($G11="","",$G11+IF($E11=0,1,IF($E11=1,1,IF($E11=2,2,IF($E11=3,4,IF($E11=4,7,14)))))) | I11: =IF($G11="","Mới",IF($H11<=TODAY(),"ĐẾN HẠN","Lịch")) | J11: =IF($I11="ĐẾN HẠN",COUNTIF($I$2:$I11,"ĐẾN HẠN"),"")
A12: a0_sound_011 | B12: =IFERROR(VLOOKUP($A12,VOCAB!$A$2:$L$1500,5,FALSE),"") | C12: =IFERROR(VLOOKUP($A12,VOCAB!$A$2:$L$1500,6,FALSE),"") | D12: =IFERROR(VLOOKUP($A12,VOCAB!$A$2:$L$1500,8,FALSE),"") | H12: =IF($G12="","",$G12+IF($E12=0,1,IF($E12=1,1,IF($E12=2,2,IF($E12=3,4,IF($E12=4,7,14)))))) | I12: =IF($G12="","Mới",IF($H12<=TODAY(),"ĐẾN HẠN","Lịch")) | J12: =IF($I12="ĐẾN HẠN",COUNTIF($I$2:$I12,"ĐẾN HẠN"),"")
A13: a0_sound_012 | B13: =IFERROR(VLOOKUP($A13,VOCAB!$A$2:$L$1500,5,FALSE),"") | C13: =IFERROR(VLOOKUP($A13,VOCAB!$A$2:$L$1500,6,FALSE),"") | D13: =IFERROR(VLOOKUP($A13,VOCAB!$A$2:$L$1500,8,FALSE),"") | H13: =IF($G13="","",$G13+IF($E13=0,1,IF($E13=1,1,IF($E13=2,2,IF($E13=3,4,IF($E13=4,7,14)))))) | I13: =IF($G13="","Mới",IF($H13<=TODAY(),"ĐẾN HẠN","Lịch")) | J13: =IF($I13="ĐẾN HẠN",COUNTIF($I$2:$I13,"ĐẾN HẠN"),"")
... A249: b1_work_012 | B249: =IFERROR(VLOOKUP($A249,VOCAB!$A$2:$L$1500,5,FALSE),"") | C249: =IFERROR(VLOOKUP($A249,VOCAB!$A$2:$L$1500,6,FALSE),"") | D249: =IFERROR(VLOOKUP($A249,VOCAB!$A$2:$L$1500,8,FALSE),"") | H249: =IF($G249="","",$G249+IF($E249=0,1,IF($E249=1,1,IF($E249=2,2,IF($E249=3,4,IF($E249=4,7,14)))))) | I249: =IF($G249="","Mới",IF($H249<=TODAY(),"ĐẾN HẠN","Lịch")) | J249: =IF($I249="ĐẾN HẠN",COUNTIF($I$2:$I249,"ĐẾN HẠN"),"")

Sheet GRAMMAR
A1: ID | B1: Level | C1: Chủ đề | D1: Công thức | E1: Ví dụ | F1: Lỗi hay gặp | G1: Bài luyện | H1: Mastery 0-5 | I1: Ngày học gần nhất | J1: Ngày ôn tới | K1: Trạng thái | L1: Thứ tự đến hạn | M1: Số ngày trong lịch
A2: GA01 | B2: A0 | C2: Verb BE | D2: I am / You are / He is / She is / It is | E2: I am a student. | F2: Using do with BE: "I do am a student" | G2: Change 20 sentences to BE | J2: =IF($I2="","",$I2+IF($H2=0,3,IF($H2=1,4,IF($H2=2,7,IF($H2=3,14,IF($H2=4,21,30)))))) | K2: =IF($I2="","Chưa học",IF($J2<=TODAY(),"ĐẾN HẠN","Lịch")) | L2: =IF($K2="ĐẾN HẠN",COUNTIF($K$2:$K2,"ĐẾN HẠN"),"") | M2: =SUMPRODUCT(--ISNUMBER(SEARCH($A2,PLAN_180!$I$2:$I$181)))
A3: GA02 | B3: A0 | C3: Subject pronouns | D3: I / you / he / she / it / we / they | E3: She is my friend. | F3: Mixing subject and object: "Him is my friend" | G3: Substitution drill, 10 lines | J3: =IF($I3="","",$I3+IF($H3=0,3,IF($H3=1,4,IF($H3=2,7,IF($H3=3,14,IF($H3=4,21,30)))))) | K3: =IF($I3="","Chưa học",IF($J3<=TODAY(),"ĐẾN HẠN","Lịch")) | L3: =IF($K3="ĐẾN HẠN",COUNTIF($K$2:$K3,"ĐẾN HẠN"),"") | M3: =SUMPRODUCT(--ISNUMBER(SEARCH($A3,PLAN_180!$I$2:$I$181)))
A4: GA03 | B4: A0 | C4: Possessive adjectives | D4: my / your / his / her / its / our / their | E4: This is my mother. | F4: Using he's for his: "This is he book" | G4: Label 15 things in a family photo | J4: =IF($I4="","",$I4+IF($H4=0,3,IF($H4=1,4,IF($H4=2,7,IF($H4=3,14,IF($H4=4,21,30)))))) | K4: =IF($I4="","Chưa học",IF($J4<=TODAY(),"ĐẾN HẠN","Lịch")) | L4: =IF($K4="ĐẾN HẠN",COUNTIF($K$2:$K4,"ĐẾN HẠN"),"") | M4: =SUMPRODUCT(--ISNUMBER(SEARCH($A4,PLAN_180!$I$2:$I$181)))
A5: GA04 | B5: A0 | C5: This / That / These / Those | D5: this + singular near, that + singular far, these/those + plural | E5: This is my pen. Those are her shoes. | F5: these is / that are | G5: Point and name 20 objects | J5: =IF($I5="","",$I5+IF($H5=0,3,IF($H5=1,4,IF($H5=2,7,IF($H5=3,14,IF($H5=4,21,30)))))) | K5: =IF($I5="","Chưa học",IF($J5<=TODAY(),"ĐẾN HẠN","Lịch")) | L5: =IF($K5="ĐẾN HẠN",COUNTIF($K$2:$K5,"ĐẾN HẠN"),"") | M5: =SUMPRODUCT(--ISNUMBER(SEARCH($A5,PLAN_180!$I$2:$I$181)))
A6: GA05 | B6: A0 | C6: There is / There are | D6: There is + singular, There are + plural | E6: There are two books on the table. | F6: Using is with a plural: "There is two books" | G6: Describe a room in 10 sentences | J6: =IF($I6="","",$I6+IF($H6=0,3,IF($H6=1,4,IF($H6=2,7,IF($H6=3,14,IF($H6=4,21,30)))))) | K6: =IF($I6="","Chưa học",IF($J6<=TODAY(),"ĐẾN HẠN","Lịch")) | L6: =IF($K6="ĐẾN HẠN",COUNTIF($K$2:$K6,"ĐẾN HẠN"),"") | M6: =SUMPRODUCT(--ISNUMBER(SEARCH($A6,PLAN_180!$I$2:$I$181)))
A7: GA06 | B7: A0 | C7: Wh- questions | D7: What / Where / Who / When / Why / How + BE or DO | E7: Where are you from? | F7: Wrong auxiliary or missing BE: "Where you from?" | G7: Ask and answer 20 questions | J7: =IF($I7="","",$I7+IF($H7=0,3,IF($H7=1,4,IF($H7=2,7,IF($H7=3,14,IF($H7=4,21,30)))))) | K7: =IF($I7="","Chưa học",IF($J7<=TODAY(),"ĐẾN HẠN","Lịch")) | L7: =IF($K7="ĐẾN HẠN",COUNTIF($K$2:$K7,"ĐẾN HẠN"),"") | M7: =SUMPRODUCT(--ISNUMBER(SEARCH($A7,PLAN_180!$I$2:$I$181)))
A8: GA11 | B8: A1 | C8: Present Simple | D8: S + V(s/es); negative don't / doesn't | E8: She works every day. | F8: Forgetting the -s: "She work every day" | G8: Write 10 sentences about your routine | J8: =IF($I8="","",$I8+IF($H8=0,3,IF($H8=1,4,IF($H8=2,7,IF($H8=3,14,IF($H8=4,21,30)))))) | K8: =IF($I8="","Chưa học",IF($J8<=TODAY(),"ĐẾN HẠN","Lịch")) | L8: =IF($K8="ĐẾN HẠN",COUNTIF($K$2:$K8,"ĐẾN HẠN"),"") | M8: =SUMPRODUCT(--ISNUMBER(SEARCH($A8,PLAN_180!$I$2:$I$181)))
A9: GA12 | B9: A1 | C9: Present Continuous | D9: be + V-ing | E9: I am studying now. | F9: Using present simple for right now: "I study now" | G9: Describe 10 actions happening now | J9: =IF($I9="","",$I9+IF($H9=0,3,IF($H9=1,4,IF($H9=2,7,IF($H9=3,14,IF($H9=4,21,30)))))) | K9: =IF($I9="","Chưa học",IF($J9<=TODAY(),"ĐẾN HẠN","Lịch")) | L9: =IF($K9="ĐẾN HẠN",COUNTIF($K$2:$K9,"ĐẾN HẠN"),"") | M9: =SUMPRODUCT(--ISNUMBER(SEARCH($A9,PLAN_180!$I$2:$I$181)))
A10: GA13 | B10: A1 | C10: Past Simple | D10: S + V2; negative did not + V | E10: I visited Hue last week. | F10: Double past marking: "I didn't went" | G10: Tell a one-minute past story | J10: =IF($I10="","",$I10+IF($H10=0,3,IF($H10=1,4,IF($H10=2,7,IF($H10=3,14,IF($H10=4,21,30)))))) | K10: =IF($I10="","Chưa học",IF($J10<=TODAY(),"ĐẾN HẠN","Lịch")) | L10: =IF($K10="ĐẾN HẠN",COUNTIF($K$2:$K10,"ĐẾN HẠN"),"") | M10: =SUMPRODUCT(--ISNUMBER(SEARCH($A10,PLAN_180!$I$2:$I$181)))
A11: GA14 | B11: A1 | C11: Future with going to | D11: be + going to + V | E11: I am going to study tonight. | F11: Missing BE: "I going to study" | G11: Talk about your weekend plans | J11: =IF($I11="","",$I11+IF($H11=0,3,IF($H11=1,4,IF($H11=2,7,IF($H11=3,14,IF($H11=4,21,30)))))) | K11: =IF($I11="","Chưa học",IF($J11<=TODAY(),"ĐẾN HẠN","Lịch")) | L11: =IF($K11="ĐẾN HẠN",COUNTIF($K$2:$K11,"ĐẾN HẠN"),"") | M11: =SUMPRODUCT(--ISNUMBER(SEARCH($A11,PLAN_180!$I$2:$I$181)))
A12: GA15 | B12: A1 | C12: Can / Can't | D12: can + V (no to, no -s) | E12: She can swim, but she can't drive. | F12: Adding to: "She can to swim" | G12: Say 10 abilities and 10 inabilities | J12: =IF($I12="","",$I12+IF($H12=0,3,IF($H12=1,4,IF($H12=2,7,IF($H12=3,14,IF($H12=4,21,30)))))) | K12: =IF($I12="","Chưa học",IF($J12<=TODAY(),"ĐẾN HẠN","Lịch")) | L12: =IF($K12="ĐẾN HẠN",COUNTIF($K$2:$K12,"ĐẾN HẠN"),"") | M12: =SUMPRODUCT(--ISNUMBER(SEARCH($A12,PLAN_180!$I$2:$I$181)))
A13: GA16 | B13: A1 | C13: Countable / Uncountable | D13: some / any / much / many / a few / a little | E13: I need some water and a few apples. | F13: many water / much books | G13: Sort 30 nouns and write 10 shopping lines | J13: =IF($I13="","",$I13+IF($H13=0,3,IF($H13=1,4,IF($H13=2,7,IF($H13=3,14,IF($H13=4,21,30)))))) | K13: =IF($I13="","Chưa học",IF($J13<=TODAY(),"ĐẾN HẠN","Lịch")) | L13: =IF($K13="ĐẾN HẠN",COUNTIF($K$2:$K13,"ĐẾN HẠN"),"") | M13: =SUMPRODUCT(--ISNUMBER(SEARCH($A13,PLAN_180!$I$2:$I$181)))
... A26: GB15 | B26: B1 | C26: Linking phrases for speaking & writing | D26: first of all / however / in addition / to sum up | E26: First of all, let me explain the problem. | F26: Listing ideas with no connectors at all | G26: Outline and deliver a 2-minute talk | J26: =IF($I26="","",$I26+IF($H26=0,3,IF($H26=1,4,IF($H26=2,7,IF($H26=3,14,IF($H26=4,21,30)))))) | K26: =IF($I26="","Chưa học",IF($J26<=TODAY(),"ĐẾN HẠN","Lịch")) | L26: =IF($K26="ĐẾN HẠN",COUNTIF($K$2:$K26,"ĐẾN HẠN"),"") | M26: =SUMPRODUCT(--ISNUMBER(SEARCH($A26,PLAN_180!$I$2:$I$181)))

Sheet CURRICULUM
A1: ID | B1: Level | C1: Module | D1: Chủ đề | E1: Ngữ pháp | F1: Từ vựng trọng tâm | G1: Nghe | H1: Nói | I1: Đọc | J1: Viết | K1: Ưu tiên | L1: Số ngày trong lịch | M1: Số ngày đã xong
A2: A0-001 | B2: A0 | C2: Foundation | D2: Alphabet & spelling | E2: — | F2: alphabet, letter names | G2: letter sounds | H2: spell your name | I2: read letters | J2: write the alphabet | K2: P1 | L2: =COUNTIF(PLAN_180!$G$2:$G$181,$A2) | M2: =COUNTIFS(PLAN_180!$G$2:$G$181,$A2,PROGRESS!$E$2:$E$181,"Yes")
A3: A0-002 | B3: A0 | C3: Pronunciation | D3: Vowels & consonants | E3: — | F3: basic sound words | G3: identify sounds | H3: repeat sounds | I3: sound recognition | J3: — | K3: P1 | L3: =COUNTIF(PLAN_180!$G$2:$G$181,$A3) | M3: =COUNTIFS(PLAN_180!$G$2:$G$181,$A3,PROGRESS!$E$2:$E$181,"Yes")
A4: A0-003 | B4: A0 | C4: Vocabulary | D4: Numbers & time | E4: — | F4: numbers, clock, days | G4: short number audio | H4: say the time | I4: read numbers | J4: write numbers | K4: P1 | L4: =COUNTIF(PLAN_180!$G$2:$G$181,$A4) | M4: =COUNTIFS(PLAN_180!$G$2:$G$181,$A4,PROGRESS!$E$2:$E$181,"Yes")
A5: A0-004 | B5: A0 | C5: Communication | D5: Greetings & introductions | E5: GA01 Verb BE | F5: hello, name, country | G5: intro dialogue | H5: introduce yourself | I5: read a mini dialogue | J5: write an introduction | K5: P1 | L5: =COUNTIF(PLAN_180!$G$2:$G$181,$A5) | M5: =COUNTIFS(PLAN_180!$G$2:$G$181,$A5,PROGRESS!$E$2:$E$181,"Yes")
A6: A0-005 | B6: A0 | C6: Grammar | D6: Pronouns & BE | E6: GA01 Verb BE; GA02 Subject pronouns | F6: I, you, he, she, we, they | G6: BE sentences | H6: make 10 sentences | I6: read sentences | J6: write 10 sentences | K6: P1 | L6: =COUNTIF(PLAN_180!$G$2:$G$181,$A6) | M6: =COUNTIFS(PLAN_180!$G$2:$G$181,$A6,PROGRESS!$E$2:$E$181,"Yes")
A7: A0-006 | B7: A0 | C7: Grammar | D7: This / That / These / Those | E7: GA04 This / That / These / Those | F7: everyday objects | G7: object descriptions | H7: point and name | I7: short text | J7: write labels | K7: P1 | L7: =COUNTIF(PLAN_180!$G$2:$G$181,$A7) | M7: =COUNTIFS(PLAN_180!$G$2:$G$181,$A7,PROGRESS!$E$2:$E$181,"Yes")
A8: A0-007 | B8: A0 | C8: Grammar | D8: There is / There are | E8: GA05 There is / There are | F8: room & place words | G8: descriptions | H8: describe your room | I8: room text | J8: room description | K8: P1 | L8: =COUNTIF(PLAN_180!$G$2:$G$181,$A8) | M8: =COUNTIFS(PLAN_180!$G$2:$G$181,$A8,PROGRESS!$E$2:$E$181,"Yes")
A9: A0-008 | B9: A0 | C9: Communication | D9: Family & people | E9: GA03 Possessive adjectives | F9: family, jobs, adjectives | G9: family dialogue | H9: describe your family | I9: short profile | J9: write a profile | K9: P1 | L9: =COUNTIF(PLAN_180!$G$2:$G$181,$A9) | M9: =COUNTIFS(PLAN_180!$G$2:$G$181,$A9,PROGRESS!$E$2:$E$181,"Yes")
A10: A0-009 | B10: A0 | C10: Vocabulary | D10: Food & drinks | E10: — | F10: common food and drinks | G10: restaurant phrases | H10: order food | I10: menu reading | J10: a simple order | K10: P1 | L10: =COUNTIF(PLAN_180!$G$2:$G$181,$A10) | M10: =COUNTIFS(PLAN_180!$G$2:$G$181,$A10,PROGRESS!$E$2:$E$181,"Yes")
A11: A0-010 | B11: A0 | C11: Grammar | D11: Basic questions | E11: GA06 Wh- questions | F11: question words | G11: Q&A | H11: ask and answer | I11: read Q&A | J11: write questions | K11: P1 | L11: =COUNTIF(PLAN_180!$G$2:$G$181,$A11) | M11: =COUNTIFS(PLAN_180!$G$2:$G$181,$A11,PROGRESS!$E$2:$E$181,"Yes")
A12: A1-011 | B12: A1 | C12: Grammar | D12: Present Simple | E12: GA11 Present Simple | F12: daily routine | G12: routine audio | H12: talk about your routine | I12: daily text | J12: routine paragraph | K12: P1 | L12: =COUNTIF(PLAN_180!$G$2:$G$181,$A12) | M12: =COUNTIFS(PLAN_180!$G$2:$G$181,$A12,PROGRESS!$E$2:$E$181,"Yes")
A13: A1-012 | B13: A1 | C13: Grammar | D13: Present Continuous | E13: GA12 Present Continuous | F13: activities | G13: activity audio | H13: describe what is happening now | I13: short story | J13: current activity | K13: P1 | L13: =COUNTIF(PLAN_180!$G$2:$G$181,$A13) | M13: =COUNTIFS(PLAN_180!$G$2:$G$181,$A13,PROGRESS!$E$2:$E$181,"Yes")
... A36: B1-035 | B36: B1 | C36: Writing | D36: Opinion paragraph | E36: GB15 Linking phrases for speaking & writing | F36: argument vocabulary | G36: short talk | H36: give your opinion | I36: opinion article | J36: 150-word paragraph | K36: P1 | L36: =COUNTIF(PLAN_180!$G$2:$G$181,$A36) | M36: =COUNTIFS(PLAN_180!$G$2:$G$181,$A36,PROGRESS!$E$2:$E$181,"Yes")

Sheet EXERCISES
A1: ID | B1: Level | C1: Kỹ năng | D1: Chủ đề | E1: CurriculumID | F1: Dạng | G1: Câu hỏi / Nhiệm vụ | H1: Đáp án | I1: Độ khó
A2: E001 | B2: A0 | C2: Grammar | D2: Verb BE | E2: A0-005 | F2: Fill blank | G2: I ___ a student. | H2: am | I2: Easy
A3: E002 | B3: A0 | C3: Vocabulary | D3: Greetings | E3: A0-004 | F3: Translate | G3: Dịch: Xin chào. | H3: Hello | I3: Easy
A4: E003 | B4: A0 | C4: Speaking | D4: Introduction | E4: A0-004 | F4: Speak | G4: Nói 5 câu giới thiệu bản thân. | H4: Checklist: name / country / job / hobby / goal | I4: Easy
A5: E004 | B5: A1 | C5: Grammar | D5: Present Simple | E5: A1-011 | F5: Correct error | G5: She go to school every day. | H5: She goes to school every day. | I5: Easy
A6: E005 | B6: A1 | C6: Listening | D6: Daily routine | E6: A1-011 | F6: Listen + note | G6: Ghi lại 5 hoạt động nghe được. | H6: Self-check | I6: Medium
A7: E006 | B7: A1 | C7: Writing | D7: Daily routine | E7: A1-011 | F7: Write | G7: Viết 60 từ về một ngày của bạn. | H7: Checklist: thì hiện tại, trạng từ tần suất, liên từ | I7: Medium
A8: E007 | B8: A2 | C8: Grammar | D8: Present Perfect | E8: A2-020 | F8: Fill blank | G8: I ___ never ___ to Japan. | H8: have / been | I8: Medium
A9: E008 | B9: A2 | C9: Speaking | D9: Experience | E9: A2-020 | F9: Roleplay | G9: Kể một trải nghiệm đáng nhớ trong 1 phút. | H9: Fluency + accuracy | I9: Medium
A10: E009 | B10: B1 | C10: Writing | D10: Opinion | E10: B1-035 | F10: Paragraph | G10: Should students use AI for learning? Write 150 words. | H10: Position + reasons + example + conclusion | I10: Medium
A11: E010 | B11: B1 | C11: Speaking | D11: Opinion | E11: B1-035 | F11: Discussion | G11: Give 3 reasons for your opinion. | H11: Clarity + examples | I11: Medium

Sheet RESOURCES
A1: ID | B1: Nguồn | C1: Level | D1: Kỹ năng | E1: Chủ đề | F1: Kiểu | G1: Miễn phí | H1: URL | I1: Dùng khi nào | J1: Ghi chú
A2: R001 | B2: British Council LearnEnglish | C2: A1–B1 | D2: All | E2: Bài luyện theo cấp độ CEFR | F2: Website | G2: YES | H2: https://learnenglish.britishcouncil.org/ | I2: Chọn bài đúng chủ đề của tuần | J2: Nguồn chuẩn cho luyện tập theo CEFR
A3: R002 | B3: USA Learns | C3: A0–A2 | D3: All | E3: Khoá cho người mới bắt đầu | F3: Course | G3: YES | H3: https://www.usalearns.org/ | I3: Dùng làm khoá chính cho 12 tuần đầu | J3: Đặc biệt tốt cho người mất gốc
A4: R003 | B4: BBC Learning English | C4: A1–B1 | D4: Listening, Grammar, Vocabulary, Pronunciation | E4: Tiếng Anh hằng ngày | F4: Website | G4: YES | H4: https://www.bbclearningenglish.com/ | I4: 10–20 phút mỗi ngày cho phần nghe | J4: Bài ngắn, dễ giữ nhịp hằng ngày
A5: R004 | B5: VOCA | C5: A0–B1 | D5: Vocabulary | E5: Từ vựng theo cấp độ | F5: Course / Plan | G5: Tuỳ thời điểm | H5: https://www.voca.vn/ | I5: Bổ sung từ vựng khi hết nguồn trong sheet VOCAB | J5: Kiểm tra mức miễn phí trước khi dùng
A6: R005 | B6: ESL Desk | C6: A1–A2 | D6: All | E6: Lộ trình cho người mới | F6: Website | G6: YES | H6: https://esldesk.com/start/beginner | I6: Bài tập thêm khi điểm dưới 70% | J6: Chỉ dùng làm bài tập phụ

Sheet PROGRESS
A1: Ngày lịch | B1: Ngày | C1: Level | D1: Chủ đề | E1: Hoàn thành | F1: Vocabulary % | G1: Grammar % | H1: Listening % | I1: Speaking % | J1: Reading % | K1: Writing % | L1: Overall % | M1: Ghi chú
A2: =PLAN_180!$B2 | B2: =PLAN_180!$A2 | C2: =PLAN_180!$D2 | D2: =PLAN_180!$H2 | L2: =IF(COUNT($F2:$K2)=0,"",ROUND(AVERAGE($F2:$K2),0))
A3: =PLAN_180!$B3 | B3: =PLAN_180!$A3 | C3: =PLAN_180!$D3 | D3: =PLAN_180!$H3 | L3: =IF(COUNT($F3:$K3)=0,"",ROUND(AVERAGE($F3:$K3),0))
A4: =PLAN_180!$B4 | B4: =PLAN_180!$A4 | C4: =PLAN_180!$D4 | D4: =PLAN_180!$H4 | L4: =IF(COUNT($F4:$K4)=0,"",ROUND(AVERAGE($F4:$K4),0))
A5: =PLAN_180!$B5 | B5: =PLAN_180!$A5 | C5: =PLAN_180!$D5 | D5: =PLAN_180!$H5 | L5: =IF(COUNT($F5:$K5)=0,"",ROUND(AVERAGE($F5:$K5),0))
A6: =PLAN_180!$B6 | B6: =PLAN_180!$A6 | C6: =PLAN_180!$D6 | D6: =PLAN_180!$H6 | L6: =IF(COUNT($F6:$K6)=0,"",ROUND(AVERAGE($F6:$K6),0))
A7: =PLAN_180!$B7 | B7: =PLAN_180!$A7 | C7: =PLAN_180!$D7 | D7: =PLAN_180!$H7 | L7: =IF(COUNT($F7:$K7)=0,"",ROUND(AVERAGE($F7:$K7),0))
A8: =PLAN_180!$B8 | B8: =PLAN_180!$A8 | C8: =PLAN_180!$D8 | D8: =PLAN_180!$H8 | L8: =IF(COUNT($F8:$K8)=0,"",ROUND(AVERAGE($F8:$K8),0))
A9: =PLAN_180!$B9 | B9: =PLAN_180!$A9 | C9: =PLAN_180!$D9 | D9: =PLAN_180!$H9 | L9: =IF(COUNT($F9:$K9)=0,"",ROUND(AVERAGE($F9:$K9),0))
A10: =PLAN_180!$B10 | B10: =PLAN_180!$A10 | C10: =PLAN_180!$D10 | D10: =PLAN_180!$H10 | L10: =IF(COUNT($F10:$K10)=0,"",ROUND(AVERAGE($F10:$K10),0))
A11: =PLAN_180!$B11 | B11: =PLAN_180!$A11 | C11: =PLAN_180!$D11 | D11: =PLAN_180!$H11 | L11: =IF(COUNT($F11:$K11)=0,"",ROUND(AVERAGE($F11:$K11),0))
A12: =PLAN_180!$B12 | B12: =PLAN_180!$A12 | C12: =PLAN_180!$D12 | D12: =PLAN_180!$H12 | L12: =IF(COUNT($F12:$K12)=0,"",ROUND(AVERAGE($F12:$K12),0))
A13: =PLAN_180!$B13 | B13: =PLAN_180!$A13 | C13: =PLAN_180!$D13 | D13: =PLAN_180!$H13 | L13: =IF(COUNT($F13:$K13)=0,"",ROUND(AVERAGE($F13:$K13),0))
... A181: =PLAN_180!$B181 | B181: =PLAN_180!$A181 | C181: =PLAN_180!$D181 | D181: =PLAN_180!$H181 | L181: =IF(COUNT($F181:$K181)=0,"",ROUND(AVERAGE($F181:$K181),0))
